Workbook

Sheet DataOld
A1: FECHA ASIGNACION | B1: NRO_SS | C1: Column2 | D1: CONTACTO | E1: Column4 | F1: Column42 | G1: Column3 | H1: NRO_ID | I1: Column5 | J1: NOMBRE_DE_OFICINA | K1: PMS | L1: DESCRIPCION_AMPLIADA | M1: PROVINCIA | N1: MUNICIPIO | O1: DISTRITO_MUNICIPIAL | P1: SECTOR | Q1: CALLE | R1: NUMERO | S1: EMPRESA_EDIFICIO | T1: DEPTO_APTO | U1: REFERENCIA | V1: TIPO_TEL_1 | W1: TEL_1 | X1: EXT_TEL_1 | Y1: TIPO_TEL_2 | Z1: TEL_2 | AA1: EXT_TEL_2 | AB1: TIPO_TEL_3 | AC1: TEL_3 | AD1: EXT_TEL_3 | AE1: FECHA_CREACION | AF1: MOTIVO_DEL_CIERRE | AG1: ESTATUS | AH1: COMENTARIO | AI1: QUIEN RECIBE | AJ1: INFO TERCERO | AK1: FECHA DE ENTREGA2 | AL1: Comentario BPD | AM1: COLUMNA PARA INGRESAR DIRECCIONES PINNIT | AN1: Column1
A2: 45883 | B2: 4-12189084312 | C2: 45883 | D2: ANGELICA YINNAIDA CUSTODIO BAEZ | E2: =VLOOKUP(DataOld!$B2,DATA!B:H,7,FALSE) -> #N/A | F2: =DataOld!$D2=DataOld!$E2 -> #N/A | G2: =VLOOKUP(DataOld!$B2,DATA!B:G,6,FALSE) -> #N/A | H2: 01300505086 | I2: =DataOld!$H2=DataOld!$G2 -> #N/A | J2: 159-OFICINA BANI I | K2: DISTRITO NACIONAL;SANTO DOMINGO;Altos de arroyo hond | L2: DISTRITO NACIONAL-SANTO DOMINGO-SANTO DOMINGO DE GUZMAN-Altos de arroyo hond-Avenida Monumental-0-Resid Nuevas Terrazas-AJ102-Resid Frente a Indomaca-C-8095057328-0-R-8099082845-0-C-0-0 | M2: DISTRITO NACIONAL | N2: SANTO DOMINGO | O2: SANTO DOMINGO DE GUZMAN | P2: Altos de arroyo hond | Q2: Avenida Monumental | R2: 0 | S2: Resid Nuevas Terrazas | T2: AJ102 | U2: Resid Frente a Indomaca | V2: C | W2: 8095057328 | X2: 0 | Y2: R | Z2: 8099082845 | AA2: 0 | AB2: C | AC2: 0 | AD2: 0 | AE2: 45883.604 | AG2: TD- ENTREGADO
A3: 45883 | B3: 4-12188798622 | C3: 45883 | D3: VIRGINIA ELIZABETH HERNANDEZ CARABALLO | E3: =VLOOKUP(DataOld!$B3,DATA!B:H,7,FALSE) -> #N/A | F3: =DataOld!$D3=DataOld!$E3 -> #N/A | G3: =VLOOKUP(DataOld!$B3,DATA!B:G,6,FALSE) -> #N/A | H3: 40214962066 | I3: =DataOld!$H3=DataOld!$G3 -> #N/A | J3: 303-OFICINA SAMBIL | K3: DISTRITO NACIONAL;SANTO DOMINGO;Arroyo hondo III | L3: Distrito Nacional-Santo Domingo-Santo Domingo De Guzman-Arroyo hondo III-Repblica de Colombia-302-Villa Graciela Manzana E-Edificio 7-Frente al bravo apto 302-C-8299604126-0-C-8299612752-0-0-0 | M3: DISTRITO NACIONAL | N3: SANTO DOMINGO | O3: SANTO DOMINGO DE GUZMAN | P3: Arroyo hondo III | Q3: Repblica de Colombia | R3: 302 | S3: Villa Graciela Manzana E | T3: Edificio 7 | U3: Frente al bravo apto 302 | V3: C | W3: 8299604126 | X3: 0 | Y3: C | Z3: 8299612752 | AA3: 0 | AB3: 0 | AC3: 0 | AE3: 45883.575 | AG3: TD- ENTREGADO
A4: 45883 | B4: 4-12188910712 | C4: 45883 | D4: KARLA MARIEL ARIAS CABRERA | E4: =VLOOKUP(DataOld!$B4,DATA!B:H,7,FALSE) -> #N/A | F4: =DataOld!$D4=DataOld!$E4 -> #N/A | G4: =VLOOKUP(DataOld!$B4,DATA!B:G,6,FALSE) -> #N/A | H4: 40222131134 | I4: =DataOld!$H4=DataOld!$G4 -> #N/A | J4: 144-OFICINA HERRERA | K4: DISTRITO NACIONAL;SANTO DOMINGO;Bayona | L4: DISTRITO NACIONAL-SANTO DOMINGO-SANTO DOMINGO DE GUZMAN-Bayona-Anastasio Tronil-52-0-0-casa 52-R-8493573029-0-C-8093306209-0-C-0-0 | M4: DISTRITO NACIONAL | N4: SANTO DOMINGO | O4: SANTO DOMINGO DE GUZMAN | P4: Bayona | Q4: Anastasio Tronil | R4: 52 | S4: 0 | T4: 0 | U4: casa 52 | V4: R | W4: 8493573029 | X4: 0 | Y4: C | Z4: 8093306209 | AA4: 0 | AB4: C | AC4: 0 | AD4: 0 | AE4: 45883.588 | AG4: TD- ENTREGADO
A5: 45883 | B5: 4-12188828862 | C5: 45883 | D5: ELIAN BUENO UBRI | E5: =VLOOKUP(DataOld!$B5,DATA!B:H,7,FALSE) -> #N/A | F5: =DataOld!$D5=DataOld!$E5 -> #N/A | G5: =VLOOKUP(DataOld!$B5,DATA!B:G,6,FALSE) -> #N/A | H5: 40232370011 | I5: =DataOld!$H5=DataOld!$G5 -> #N/A | J5: 137-OFICINA WINSTON CHURCHILL | K5: DISTRITO NACIONAL;SANTO DOMINGO;Bella vista | L5: DISTRITO NACIONAL-SANTO DOMINGO-SANTO DOMINGO DE GUZMAN-Bella vista-sarasota-62-ccc papeleria-2do nivel-dentro de almacenes unidos-C-8299137334-0-T-8295576507-0000-C-0-0 | M5: DISTRITO NACIONAL | N5: SANTO DOMINGO | O5: SANTO DOMINGO DE GUZMAN | P5: Bella vista | Q5: sarasota | R5: 62 | S5: ccc papeleria | T5: 2do nivel | U5: dentro de almacenes unidos | V5: C | W5: 8299137334 | X5: 0 | Y5: T | Z5: 8295576507 | AA5: 0000 | AB5: C | AC5: 0 | AD5: 0 | AE5: 45883.582 | AG5: TD- ENTREGADO
A6: 45883 | B6: 4-12189276732 | C6: 45883 | D6: DANIEL GUZMAN TORREZ | E6: =VLOOKUP(DataOld!$B6,DATA!B:H,7,FALSE) -> #N/A | F6: =DataOld!$D6=DataOld!$E6 -> #N/A | G6: =VLOOKUP(DataOld!$B6,DATA!B:G,6,FALSE) -> #N/A | H6: 00117882977 | I6: =DataOld!$H6=DataOld!$G6 -> #N/A | J6: 150-OFICINA PLAZA COMERCIAL PARQUE HABITAT | K6: DISTRITO NACIONAL;SANTO DOMINGO;cuesta hermosas 2 | L6: DISTRITO NACIONAL-SANTO DOMINGO-SANTO DOMINGO DE GUZMAN-cuesta hermosas 2-3ra del rios-31-jardineros-casa 31-trabajo dosmetico desde 2008-C-8493792031-0-T-8095653018-0-C-8097292133-0 | M6: DISTRITO NACIONAL | N6: SANTO DOMINGO | O6: SANTO DOMINGO DE GUZMAN | P6: cuesta hermosas 2 | Q6: 3ra del rios | R6: 31 | S6: jardineros | T6: casa 31 | U6: trabajo dosmetico desde 2008 | V6: C | W6: 8493792031 | X6: 0 | Y6: T | Z6: 8095653018 | AA6: 0 | AB6: C | AC6: 8097292133 | AD6: 0 | AE6: 45883.632 | AG6: TD- ENTREGADO
A7: 45883 | B7: 4-12189239872 | C7: 45883 | D7: ALIMER LOPEZ DE LOS SANTOS | E7: =VLOOKUP(DataOld!$B7,DATA!B:H,7,FALSE) -> #N/A | F7: =DataOld!$D7=DataOld!$E7 -> #N/A | G7: =VLOOKUP(DataOld!$B7,DATA!B:G,6,FALSE) -> #N/A | H7: 40209048608 | I7: =DataOld!$H7=DataOld!$G7 -> #N/A | J7: 464-OCCIDENTALL MALL | K7: DISTRITO NACIONAL;SANTO DOMINGO;Ensanche Kennedy | L7: Distrito Nacional-Santo Domingo-Santo Domingo De Guzman-Ensanche Kennedy -Av John F Kennedy-1-Humano Seguros -Sac Inter-Alimer Lpez-C-8098017677-0-C-8293233001-0-0-0 | M7: DISTRITO NACIONAL | N7: SANTO DOMINGO | O7: SANTO DOMINGO DE GUZMAN | P7: Ensanche Kennedy | Q7: Av John F Kennedy | R7: 1 | S7: Humano Seguros | T7: Sac Inter | U7: Alimer Lpez | V7: C | W7: 8098017677 | X7: 0 | Y7: C | Z7: 8293233001 | AA7: 0 | AB7: 0 | AC7: 0 | AE7: 45883.633 | AG7: TD- ENTREGADO | AL7: CLIENTE INDICA YA LA TIENE
A8: 45883 | B8: 4-12189095572 | C8: 45883 | D8: GEORGE JOSE PINA ROBLES | E8: =VLOOKUP(DataOld!$B8,DATA!B:H,7,FALSE) -> #N/A | F8: =DataOld!$D8=DataOld!$E8 -> #N/A | G8: =VLOOKUP(DataOld!$B8,DATA!B:G,6,FALSE) -> #N/A | H8: 40213113240 | I8: =DataOld!$H8=DataOld!$G8 -> #N/A | J8: 139-OFICINA NACO | K8: DISTRITO NACIONAL;SANTO DOMINGO;Ensanche luperon | L8: Distrito Nacional-Santo Domingo-Santo Domingo De Guzman-Ensanche luperon -25 este-19-Soluciones oficinas Diaz -VENTAS SOD-Preguntar por GEORGE VENTAS-C-8299643293-0-C-8293034089-0-0-0 | M8: DISTRITO NACIONAL | N8: SANTO DOMINGO | O8: SANTO DOMINGO DE GUZMAN | P8: Ensanche luperon | Q8: 25 este | R8: 19 | S8: Soluciones oficinas Diaz | T8: VENTAS SOD | U8: Preguntar por GEORGE VENTAS | V8: C | W8: 8299643293 | X8: 0 | Y8: C | Z8: 8293034089 | AA8: 0 | AB8: 0 | AC8: 0 | AE8: 45883.61 | AG8: TD- ENTREGADO
A9: 45883 | B9: 4-12187995692 | C9: 45883 | D9: JONNY EDWARD LORENZO SANCHEZ | E9: =VLOOKUP(DataOld!$B9,DATA!B:H,7,FALSE) -> #N/A | F9: =DataOld!$D9=DataOld!$E9 -> #N/A | G9: =VLOOKUP(DataOld!$B9,DATA!B:G,6,FALSE) -> #N/A | H9: 00101728046 | I9: =DataOld!$H9=DataOld!$G9 -> #N/A | J9: 137-OFICINA WINSTON CHURCHILL | K9: DISTRITO NACIONAL;SANTO DOMINGO;Evaristo Morales | L9: Distrito Nacional-Santo Domingo-Santo Domingo De Guzman-Evaristo Morales -Calle Viriato Fiallo-57-Agencia Milena Tours-Comercial-0-C-8299629262-0-T-8095666076-221-0-0 | M9: DISTRITO NACIONAL | N9: SANTO DOMINGO | O9: SANTO DOMINGO DE GUZMAN | P9: Evaristo Morales | Q9: Calle Viriato Fiallo | R9: 57 | S9: Agencia Milena Tours | T9: Comercial | U9: 0 | V9: C | W9: 8299629262 | X9: 0 | Y9: T | Z9: 8095666076 | AA9: 221 | AB9: 0 | AC9: 0 | AE9: 45883.513 | AG9: TD- ENTREGADO
A10: 45883 | B10: 4-12188179862 | C10: 45883 | D10: JOAN RAFAEL MEJIA FERREIRAS | E10: =VLOOKUP(DataOld!$B10,DATA!B:H,7,FALSE) -> #N/A | F10: =DataOld!$D10=DataOld!$E10 -> #N/A | G10: =VLOOKUP(DataOld!$B10,DATA!B:G,6,FALSE) -> #N/A | H10: 00118948504 | I10: =DataOld!$H10=DataOld!$G10 -> #N/A | J10: 137-OFICINA WINSTON CHURCHILL | K10: DISTRITO NACIONAL;SANTO DOMINGO;Evaristo Morales | L10: DISTRITO NACIONAL-SANTO DOMINGO-SANTO DOMINGO DE GUZMAN-Evaristo Morales-Luis F Thomen-104-contemega-finanzas-0-C-8295188321-0-T-8092275558-0-C-0-0 | M10: DISTRITO NACIONAL | N10: SANTO DOMINGO | O10: SANTO DOMINGO DE GUZMAN | P10: Evaristo Morales | Q10: Luis F Thomen | R10: 104 | S10: contemega | T10: finanzas | U10: 0 | V10: C | W10: 8295188321 | X10: 0 | Y10: T | Z10: 8092275558 | AA10: 0 | AB10: C | AC10: 0 | AD10: 0 | AE10: 45883.535 | AG10: TD- ENTREGADO
A11: 45883 | B11: 4-12188709602 | C11: 45883 | D11: FRANCISCO NICOLAS JOSE PEREZ | E11: =VLOOKUP(DataOld!$B11,DATA!B:H,7,FALSE) -> #N/A | F11: =DataOld!$D11=DataOld!$E11 -> #N/A | G11: =VLOOKUP(DataOld!$B11,DATA!B:G,6,FALSE) -> #N/A | H11: 40214693992 | I11: =DataOld!$H11=DataOld!$G11 -> #N/A | J11: 196-OFICINA SAN VICENTE DE PAUL | K11: DISTRITO NACIONAL;SANTO DOMINGO;Evaristo Morales | L11: Distrito Nacional-Santo Domingo-Santo Domingo De Guzman-Evaristo Morales-Max Henrinquez Urena-98-Torre Lia Kamille X-6B-0-C-8099142302-0-C-8297189305-0-0-0 | M11: DISTRITO NACIONAL | N11: SANTO DOMINGO | O11: SANTO DOMINGO DE GUZMAN | P11: Evaristo Morales | Q11: Max Henrinquez Urena | R11: 98 | S11: Torre Lia Kamille X | T11: 6B | U11: 0 | V11: C | W11: 8099142302 | X11: 0 | Y11: C | Z11: 8297189305 | AA11: 0 | AB11: 0 | AC11: 0 | AE11: 45883.564 | AG11: TD- ENTREGADO
A12: 45883 | B12: 4-12188985282 | C12: 45883 | D12: SORANGEL IVETTE ARIAS PAYANO | E12: =VLOOKUP(DataOld!$B12,DATA!B:H,7,FALSE) -> #N/A | F12: =DataOld!$D12=DataOld!$E12 -> #N/A | G12: =VLOOKUP(DataOld!$B12,DATA!B:G,6,FALSE) -> #N/A | H12: 40224783130 | I12: =DataOld!$H12=DataOld!$G12 -> #N/A | J12: 273-OFICINA CAMPUS UCE SPM | K12: DISTRITO NACIONAL;SANTO DOMINGO;Honduras del Norte | L12: DISTRITO NACIONAL-SANTO DOMINGO-SANTO DOMINGO DE GUZMAN-Honduras del Norte-Avenida Independenci-2266-SIHISA-A210-Plaza Atalaya encima GBC-C-8293498341-0-C-8493792101-0-C-0-0 | M12: DISTRITO NACIONAL | N12: SANTO DOMINGO | O12: cambita Garabitos | P12: Honduras del Norte | Q12: Avenida Independenci | R12: 2266 | S12: SIHISA | T12: A210 | U12: Plaza Atalaya encima GBC | V12: C | W12: 8293498341 | X12: 0 | Y12: C | Z12: 8493792101 | AA12: 0 | AB12: C | AC12: 0 | AD12: 0 | AE12: 45883.6 | AG12: TD- ENTREGADO
A13: 45883 | B13: 4-12188107222 | C13: 45883 | D13: CLAUDIA MIGUELINA REYES GUZMAN | E13: =VLOOKUP(DataOld!$B13,DATA!B:H,7,FALSE) -> #N/A | F13: =DataOld!$D13=DataOld!$E13 -> #N/A | G13: =VLOOKUP(DataOld!$B13,DATA!B:G,6,FALSE) -> #N/A | H13: 00117248633 | I13: =DataOld!$H13=DataOld!$G13 -> #N/A | J13: 140-OFICINA EL PORTAL | K13: DISTRITO NACIONAL;SANTO DOMINGO;Las Praderas | L13: Distrito Nacional-Santo Domingo-Santo Domingo De Guzman-Las Praderas -Libertad -41-Cuatro Cuerdas Estudio M-NA-Misma calle de Almacenes El -C-8299171304-0-T-8097407514-1-T-8095342917-02 | M13: DISTRITO NACIONAL | N13: SANTO DOMINGO | O13: SANTO DOMINGO DE GUZMAN | P13: Las Praderas | Q13: Libertad | R13: 41 | S13: Cuatro Cuerdas Estudio M | T13: NA | U13: Misma calle de Almacenes El | V13: C | W13: 8299171304 | X13: 0 | Y13: T | Z13: 8097407514 | AA13: 1 | AB13: T | AC13: 8095342917 | AD13: 02 | AE13: 45883.536 | AG13: TD- ENTREGADO
A14: 45883 | B14: 4-12188106922 | C14: 45883 | D14: PEDRO JANEL ZORRILLA ZORRILLA | E14: =VLOOKUP(DataOld!$B14,DATA!B:H,7,FALSE) -> #N/A | F14: =DataOld!$D14=DataOld!$E14 -> #N/A | G14: =VLOOKUP(DataOld!$B14,DATA!B:G,6,FALSE) -> #N/A | H14: 40209963392 | I14: =DataOld!$H14=DataOld!$G14 -> #N/A | J14: 342-OFICINA GALERIA 360 | K14: DISTRITO NACIONAL;SANTO DOMINGO;Los Frailes | L14: Distrito Nacional-Santo Domingo-Santo Domingo De Guzman-Los Frailes -Salome urena -52-0-0-Casa segundo nivel -C-8297686283-0-C-8293494825-0-0-0 | M14: DISTRITO NACIONAL | N14: SANTO DOMINGO | O14: SANTO DOMINGO DE GUZMAN | P14: Los Frailes | Q14: Salome urena | R14: 52 | S14: 0 | T14: 0 | U14: Casa segundo nivel | V14: C | W14: 8297686283 | X14: 0 | Y14: C | Z14: 8293494825 | AA14: 0 | AB14: 0 | AC14: 0 | AE14: 45883.53 | AG14: TD- NO LE INTERESA | AH14: NUMEROS NO RESPONDEN | AL14: NO LE INTERESA, ESTA FUERA DEL PAIS
A15: 45883 | B15: 4-12187850582 | C15: 45883 | D15: LUIS SADIEL GARCIA DIAZ | E15: =VLOOKUP(DataOld!$B15,DATA!B:H,7,FALSE) -> #N/A | F15: =DataOld!$D15=DataOld!$E15 -> #N/A | G15: =VLOOKUP(DataOld!$B15,DATA!B:G,6,FALSE) -> #N/A | H15: 40213726413 | I15: =DataOld!$H15=DataOld!$G15 -> #N/A | J15: 344-OFICINA OLE LOS FRAILES | K15: DISTRITO NACIONAL;SANTO DOMINGO;Los Prados | L15: Distrito Nacional-Santo Domingo-Santo Domingo De Guzman-Los prados -Av charles sumner -54-Smarbet-Local 3b-Plaza charles sumner -C-8097127429-0-C-8295564287-0-0-0 | M15: DISTRITO NACIONAL | N15: SANTO DOMINGO | O15: SANTO DOMINGO DE GUZMAN | P15: Los Prados | Q15: Av charles sumner | R15: 54 | S15: Smarbet | T15: Local 3b | U15: Plaza charles sumner | V15: C | W15: 8097127429 | X15: 0 | Y15: C | Z15: 8295564287 | AA15: 0 | AB15: 0 | AC15: 0 | AE15: 45883.495 | AG15: TD- ENTREGADO
A16: 45883 | B16: 4-12188139092 | C16: 45883 | D16: ESTEFANIA MATOS | E16: =VLOOKUP(DataOld!$B16,DATA!B:H,7,FALSE) -> #N/A | F16: =DataOld!$D16=DataOld!$E16 -> #N/A | G16: =VLOOKUP(DataOld!$B16,DATA!B:G,6,FALSE) -> #N/A | H16: 40237205907 | I16: =DataOld!$H16=DataOld!$G16 -> #N/A | J16: 139-OFICINA NACO | K16: DISTRITO NACIONAL;SANTO DOMINGO;paraiso | L16: DISTRITO NACIONAL-SANTO DOMINGO-SANTO DOMINGO DE GUZMAN-paraiso-ponzio zabater-00-farma extra-farmacia-plaza paraiso-C-8492064868-0-C-8095673919-0-C-8094049169-0 | M16: DISTRITO NACIONAL | N16: SANTO DOMINGO | O16: SANTO DOMINGO DE GUZMAN | P16: paraiso | Q16: ponzio zabater | R16: 00 | S16: farma extra | T16: farmacia | U16: plaza paraiso | V16: C | W16: 8492064868 | X16: 0 | Y16: C | Z16: 8095673919 | AA16: 0 | AB16: C | AC16: 8094049169 | AD16: 0 | AE16: 45883.534 | AG16: TD- ENTREGADO
A17: 45883 | B17: 4-12188938362 | C17: 45883 | D17: DIEGO ALEJANDRO PUMAROL CUNILLERA | E17: =VLOOKUP(DataOld!$B17,DATA!B:H,7,FALSE) -> #N/A | F17: =DataOld!$D17=DataOld!$E17 -> #N/A | G17: =VLOOKUP(DataOld!$B17,DATA!B:G,6,FALSE) -> #N/A | H17: 40230377547 | I17: =DataOld!$H17=DataOld!$G17 -> #N/A | J17: Centro Digital Popular | K17: DISTRITO NACIONAL;SANTO DOMINGO;Piantini | L17: Distrito Nacional-Santo Domingo-Santo Domingo De Guzman-Piantini-Federico Geraldino-58-Torre palmera real-301A-0-C-8098533323-0-C-8098487707-0-0-0 | M17: DISTRITO NACIONAL | N17: SANTO DOMINGO | O17: SANTO DOMINGO DE GUZMAN | P17: Piantini | Q17: Federico Geraldino | R17: 58 | S17: Torre palmera real | T17: 301A | U17: 0 | V17: C | W17: 8098533323 | X17: 0 | Y17: C | Z17: 8098487707 | AA17: 0 | AB17: 0 | AC17: 0 | AE17: 45883.589 | AG17: TD- ENTREGADO
A18: 45883 | B18: 4-12187994612 | C18: 45883 | D18: EMER JOSE TEJEDA DIONICIO | E18: =VLOOKUP(DataOld!$B18,DATA!B:H,7,FALSE) -> #N/A | F18: =DataOld!$D18=DataOld!$E18 -> #N/A | G18: =VLOOKUP(DataOld!$B18,DATA!B:G,6,FALSE) -> #N/A | H18: 00201418597 | I18: =DataOld!$H18=DataOld!$G18 -> #N/A | J18: 141-OFICINA TORRE EMPRESARIAL 27 DE FEBRERO | K18: DISTRITO NACIONAL;SANTO DOMINGO;Serralles | L18: DISTRITO NACIONAL-SANTO DOMINGO-SANTO DOMINGO DE GUZMAN-Serralles-John F Kenedy-52-Claro Dominicana-3er Piso-0-C-8096057997-0-C-8094245121-0-C-0-0 | M18: DISTRITO NACIONAL | N18: SANTO DOMINGO | O18: SANTO DOMINGO DE GUZMAN | P18: Serralles | Q18: John F Kenedy | R18: 52 | S18: Claro Dominicana | T18: 3er Piso | U18: 0 | V18: C | W18: 8096057997 | X18: 0 | Y18: C | Z18: 8094245121 | AA18: 0 | AB18: C | AC18: 0 | AD18: 0 | AE18: 45883.508 | AG18: TD- ENTREGADO
A19: 45883 | B19: 4-12189252532 | C19: 45883 | D19: ANGEL BERTINIO MATEO BERNABE | E19: =VLOOKUP(DataOld!$B19,DATA!B:H,7,FALSE) -> #N/A | F19: =DataOld!$D19=DataOld!$E19 -> #N/A | G19: =VLOOKUP(DataOld!$B19,DATA!B:G,6,FALSE) -> #N/A | H19: 01300373261 | I19: =DataOld!$H19=DataOld!$G19 -> #N/A | J19: 201-OFICINA VILLA CONSUELO | K19: DISTRITO NACIONAL;SANTO DOMINGO;villa consuelo | L19: DISTRITO NACIONAL-SANTO DOMINGO-SANTO DOMINGO DE GUZMAN-villa consuelo-calle batazar de los-114-colmado hermanos mateo-1-frente a la banca ortiz-C-8298599580-0-C-8497500226-0-C-0-0 | M19: DISTRITO NACIONAL | N19: SANTO DOMINGO | O19: SANTO DOMINGO DE GUZMAN | P19: villa consuelo | Q19: calle batazar de los | R19: 114 | S19: colmado hermanos mateo | T19: 1 | U19: frente a la banca ortiz | V19: C | W19: 8298599580 | X19: 0 | Y19: C | Z19: 8497500226 | AA19: 0 | AB19: C | AC19: 0 | AD19: 0 | AE19: 45883.624 | AG19: TD- ENTREGADO
A20: 45883 | B20: 4-12188623782 | C20: 45883 | D20: RAFAEL ANTONIO PENA BENITEZ | E20: =VLOOKUP(DataOld!$B20,DATA!B:H,7,FALSE) -> #N/A | F20: =DataOld!$D20=DataOld!$E20 -> #N/A | G20: =VLOOKUP(DataOld!$B20,DATA!B:G,6,FALSE) -> #N/A | H20: 22300543331 | I20: =DataOld!$H20=DataOld!$G20 -> #N/A | J20: 204-OFICINA MAXIMO GOMEZ | K20: DISTRITO NACIONAL;SANTO DOMINGO;villas agricolas | L20: DISTRITO NACIONAL-SANTO DOMINGO-SANTO DOMINGO DE GUZMAN-villas agricolas-Maria montez-249-seinca-local gris-Al lado del respuesto Angher-C-8292223079-0-T-8095366571-0-C-8096142127-0 | M20: DISTRITO NACIONAL | N20: SANTO DOMINGO | O20: SANTO DOMINGO DE GUZMAN | P20: villas agricolas | Q20: Maria montez | R20: 249 | S20: seinca | T20: local gris | U20: Al lado del respuesto Angher | V20: C | W20: 8292223079 | X20: 0 | Y20: T | Z20: 8095366571 | AA20: 0 | AB20: C | AC20: 8096142127 | AD20: 0 | AE20: 45883.554 | AG20: TD- ENTREGADO
A21: 45883 | B21: 4-12188798812 | C21: 45883 | D21: JUNIOR ALBERTO RODRIGUEZ ROSARIO | E21: =VLOOKUP(DataOld!$B21,DATA!B:H,7,FALSE) -> #N/A | F21: =DataOld!$D21=DataOld!$E21 -> #N/A | G21: =VLOOKUP(DataOld!$B21,DATA!B:G,6,FALSE) -> #N/A | H21: 40241135256 | I21: =DataOld!$H21=DataOld!$G21 -> #N/A | J21: 216-OFICINA IBERIA HIGUEY | K21: LA ALTAGRACIA;HIGUEY;Centro de la ciudad | L21: La Altagracia-Higuey-Higuey-Centro de la ciudad -Agustin guerrero -58-Carlos celulares -Primer pis-Al lado de David foto color -C-8498069003-0-T-8095545138-220-0-0 | M21: LA ALTAGRACIA | N21: HIGUEY | O21: Higuey | P21: Centro de la ciudad | Q21: Agustin guerrero | R21: 58 | S21: Carlos celulares | T21: Primer pis | U21: Al lado de David foto color | V21: C | W21: 8498069003 | X21: 0 | Y21: T | Z21: 8095545138 | AA21: 220 | AB21: 0 | AC21: 0 | AE21: 45883.579 | AG21: TD- ENTREGADO
A22: 45883 | B22: 4-12188710222 | C22: 45883 | D22: YULAINI VALESCA REYES OLIVO | E22: =VLOOKUP(DataOld!$B22,DATA!B:H,7,FALSE) -> #N/A | F22: =DataOld!$D22=DataOld!$E22 -> #N/A | G22: =VLOOKUP(DataOld!$B22,DATA!B:G,6,FALSE) -> #N/A | H22: 40231668597 | I22: =DataOld!$H22=DataOld!$G22 -> #N/A | J22: 234-OFICINA PUNTA CANA | K22: LA ALTAGRACIA;HIGUEY;Los rosales | L22: La Altagracia-Higuey-Higuey-Los rosales-Urania montas -32-0-0-Casa verde con antena -C-8293188639-0-C-8092995224-0-0-0 | M22: LA ALTAGRACIA | N22: HIGUEY | O22: Higuey | P22: Los rosales | Q22: Urania montas | R22: 32 | S22: 0 | T22: 0 | U22: Casa verde con antena | V22: C | W22: 8293188639 | X22: 0 | Y22: C | Z22: 8092995224 | AA22: 0 | AB22: 0 | AC22: 0 | AE22: 45883.575 | AG22: TD- ENTREGADO
A23: 45883 | B23: 4-12188036942 | C23: 45883 | D23: ALEXANDER LUIS | E23: =VLOOKUP(DataOld!$B23,DATA!B:H,7,FALSE) -> #N/A | F23: =DataOld!$D23=DataOld!$E23 -> #N/A | G23: =VLOOKUP(DataOld!$B23,DATA!B:G,6,FALSE) -> #N/A | H23: 40233244967 | I23: =DataOld!$H23=DataOld!$G23 -> #N/A | J23: 219-OFICINA DE SERVICIOS UVERO ALTO | K23: LA ALTAGRACIA;HIGUEY;Nisibon La vacama | L23: La Altagracia-Higuey-Higuey-Nisibon La vacama -Principal -8-0-0-Antes del puente La vacama -C-8493754596-0-C-8295854121-0-0-0 | M23: LA ALTAGRACIA | N23: HIGUEY | O23: Higuey | P23: Nisibon La vacama | Q23: Principal | R23: 8 | S23: 0 | T23: 0 | U23: Antes del puente La vacama | V23: C | W23: 8493754596 | X23: 0 | Y23: C | Z23: 8295854121 | AA23: 0 | AB23: 0 | AC23: 0 | AE23: 45883.518 | AG23: TD- ENTREGADO
A24: 45883 | B24: 4-12188769322 | C24: 45883 | D24: RANCELL ALEXANDERT MONTERO | E24: =VLOOKUP(DataOld!$B24,DATA!B:H,7,FALSE) -> #N/A | F24: =DataOld!$D24=DataOld!$E24 -> #N/A | G24: =VLOOKUP(DataOld!$B24,DATA!B:G,6,FALSE) -> #N/A | H24: 40226358360 | I24: =DataOld!$H24=DataOld!$G24 -> #N/A | J24: 272-OFICINA LA OTRA BANDA, HIGUEY | K24: LA ALTAGRACIA;HIGUEY;veron | L24: LA ALTAGRACIA-HIGUEY-VERON PUNTA CANA-veron-avenida barcelo km2-13-MONTILL MOTORS-Informatic-Encargado informatica-C-8097503587-0-T-8094551515-219-T-8097233768-0 | M24: LA ALTAGRACIA | N24: HIGUEY | O24: VERON PUNTA CANA | P24: veron | Q24: avenida barcelo km2 | R24: 13 | S24: MONTILL MOTORS | T24: Informatic | U24: Encargado informatica | V24: C | W24: 8097503587 | X24: 0 | Y24: T | Z24: 8094551515 | AA24: 219 | AB24: T | AC24: 8097233768 | AD24: 0 | AE24: 45883.566 | AG24: TD- ENTREGADO
A25: 45883 | B25: 4-12189289782 | C25: 45883 | D25: REYNALDO DE LOS SANTO GONZALE | E25: =VLOOKUP(DataOld!$B25,DATA!B:H,7,FALSE) -> #N/A | F25: =DataOld!$D25=DataOld!$E25 -> #N/A | G25: =VLOOKUP(DataOld!$B25,DATA!B:G,6,FALSE) -> #N/A | H25: 07900181699 | I25: =DataOld!$H25=DataOld!$G25 -> #N/A | J25: 215-OFICINA BAVARO | K25: LA ALTAGRACIA;HIGUEY;villa europa | L25: LA ALTAGRACIA-HIGUEY-VERON PUNTA CANA-villa europa-doble via de veron-1-apt ps-si-frente al drik molly-C-8298519029-0-C-8298519023-0-C-8297743157-0 | M25: LA ALTAGRACIA | N25: HIGUEY | O25: VERON PUNTA CANA | P25: villa europa | Q25: doble via de veron | R25: 1 | S25: apt ps | T25: Si | U25: frente al drik molly | V25: C | W25: 8298519029 | X25: 0 | Y25: C | Z25: 8298519023 | AA25: 0 | AB25: C | AC25: 8297743157 | AD25: 0 | AE25: 45883.63 | AG25: TD- ENTREGADO | AL25: 8298519029/-C-8297743157-EQUIVOCADO/LE ESCRIBI X WSS A ESPERA DE RESPUESTA ME ENVIO LA UBICACION X WSS A SU VES LA ENVIE A CELERITA( RAMSES Y ARMANDO
A26: 45883 | B26: 4-12188317912 | C26: 45883 | D26: FRANCELIS YULISSA SOTO SUAZO DE SOTO | E26: =VLOOKUP(DataOld!$B26,DATA!B:H,7,FALSE) -> #N/A | F26: =DataOld!$D26=DataOld!$E26 -> #N/A | G26: =VLOOKUP(DataOld!$B26,DATA!B:G,6,FALSE) -> #N/A | H26: 00301147070 | I26: =DataOld!$H26=DataOld!$G26 -> #N/A | J26: 159-OFICINA BANI I | K26: PERAVIA;BANI;Bani | L26: Peravia-Bani-Bani-Bani-Calle Snchez-29-Laboratorio Amadita -Plaza-Plaza Bani-C-8097121229-0-C-8294205958-0-0-0 | M26: PERAVIA | N26: BANI | O26: Bani | P26: Bani | Q26: Calle Snchez | R26: 29 | S26: Laboratorio amadita | T26: Plaza | U26: Plaza Bani | V26: C | W26: 8097121229 | X26: 0 | Y26: C | Z26: 8294205958 | AA26: 0 | AB26: 0 | AC26: 0 | AE26: 45883.533 | AG26: TD- ENTREGADO
A27: 45883 | B27: 4-12188661002 | C27: 45883 | D27: NIKITA LITVINOV | E27: =VLOOKUP(DataOld!$B27,DATA!B:H,7,FALSE) -> #N/A | F27: =DataOld!$D27=DataOld!$E27 -> #N/A | G27: =VLOOKUP(DataOld!$B27,DATA!B:G,6,FALSE) -> #N/A | H27: 40245185752 | I27: =DataOld!$H27=DataOld!$G27 -> #N/A | J27: 269-OFICINA CABARETE | K27: Puerto Plata;Sosua;Ocean village | L27: Puerto Plata-Sosua-Sosua-Ocean village-Ocean village -20-0-0-0-C-8298899999-0-C-8493148881-0-0-0 | M27: Puerto Plata | N27: Sosua | O27: Sosua | P27: Ocean village | Q27: Ocean village | R27: 20 | S27: 0 | T27: 0 | U27: 0 | V27: C | W27: 8298899999 | X27: 0 | Y27: C | Z27: 8493148881 | AA27: 0 | AB27: 0 | AC27: 0 | AE27: 45883.563 | AG27: TD- ENTREGADO
A28: 45883 | B28: 4-12188009622 | C28: 45883 | D28: JOSUE DIAZ RODRIGUEZ | E28: =VLOOKUP(DataOld!$B28,DATA!B:H,7,FALSE) -> #N/A | F28: =DataOld!$D28=DataOld!$E28 -> #N/A | G28: =VLOOKUP(DataOld!$B28,DATA!B:G,6,FALSE) -> #N/A | H28: 40229911199 | I28: =DataOld!$H28=DataOld!$G28 -> #N/A | J28: 158-OFICINA PIISA HAINA | K28: SAN CRISTOBAL;BAJOS DE HAINA;Cabon | L28: San Cristobal-Bajos De Haina-Bajos De Haina-Cabon-Minerva mirabal -1651-0-0-Frente a la escuela basica -C-8292192273-0-C-8492814066-0-0-0 | M28: SAN CRISTOBAL | N28: BAJOS DE HAINA | O28: BAJOS DE HAINA | P28: Cabon | Q28: Minerva mirabal | R28: 1651 | S28: 0 | T28: 0 | U28: Frente a la escuela basica | V28: C | W28: 8292192273 | X28: 0 | Y28: C | Z28: 8492814066 | AA28: 0 | AB28: 0 | AC28: 0 | AE28: 45883.511 | AG28: TD- ENTREGADO
A29: 45883 | B29: 4-12188225562 | C29: 45883 | D29: SANTA YSABEL FIGUEREO BAUTISTA | E29: =VLOOKUP(DataOld!$B29,DATA!B:H,7,FALSE) -> #N/A | F29: =DataOld!$D29=DataOld!$E29 -> #N/A | G29: =VLOOKUP(DataOld!$B29,DATA!B:G,6,FALSE) -> #N/A | H29: 40224593570 | I29: =DataOld!$H29=DataOld!$G29 -> #N/A | J29: 155-OFICINA SAN CRISTOBAL | K29: SAN CRISTOBAL;Cambita Garabitos;El cajon | L29: San Cristobal-Cambita Garabitos-Cambita Garabitos-El cajon -Primera -1-ICI-Secretara-Frente a la bomba TLC bomba-C-8493790665-0-C-8299296460-0-0-0 | M29: SAN CRISTOBAL | N29: Cambita Garabitos | O29: Cambita Garabitos | P29: El cajon | Q29: primera | R29: 1 | S29: ICI | T29: Secretara | U29: Frente a la bomba TLC bomba | V29: C | W29: 8493790665 | X29: 0 | Y29: C | Z29: 8299296460 | AA29: 0 | AB29: 0 | AC29: 0 | AE29: 45883.529 | AG29: TD- ENTREGADO
A30: 45883 | B30: 4-12188618142 | C30: 45883 | D30: WANDER MADIER CABRERA SUERO | E30: =VLOOKUP(DataOld!$B30,DATA!B:H,7,FALSE) -> #N/A | F30: =DataOld!$D30=DataOld!$E30 -> #N/A | G30: =VLOOKUP(DataOld!$B30,DATA!B:G,6,FALSE) -> #N/A | H30: 40222594232 | I30: =DataOld!$H30=DataOld!$G30 -> #N/A | J30: 158-OFICINA PIISA HAINA | K30: SAN CRISTOBAL;SAN CRISTOBAL;Pueblo Nuevo | L30: SAN CRISTOBAL-SAN CRISTOBAL-SAN CRISTOBAL-Pueblo Nuevo-Proyecto 15-1-0-0-Cerca del Colmado Los Muchac-C-8294385418-0-C-8295696616-0-C-0-0 | M30: SAN CRISTOBAL | N30: SAN CRISTOBAL | O30: SAN CRISTOBAL | P30: Pueblo Nuevo | Q30: Proyecto 15 | R30: 1 | S30: 0 | T30: 0 | U30: Cerca del Colmado Los Muchac | V30: C | W30: 8294385418 | X30: 0 | Y30: C | Z30: 8295696616 | AA30: 0 | AB30: C | AC30: 0 | AD30: 0 | AE30: 45883.556 | AG30: TD- ENTREGADO
A31: 45883 | B31: 4-12188524552 | C31: 45883 | D31: YEREINID PEGUERO RIJO | E31: =VLOOKUP(DataOld!$B31,DATA!B:H,7,FALSE) -> #N/A | F31: =DataOld!$D31=DataOld!$E31 -> #N/A | G31: =VLOOKUP(DataOld!$B31,DATA!B:G,6,FALSE) -> #N/A | H31: 40235358294 | I31: =DataOld!$H31=DataOld!$G31 -> #N/A | J31: 273-OFICINA CAMPUS UCE SPM | K31: SAN PEDRO DE MACORIS;SAN PEDRO MACORIS;hatos de san pedro | L31: SAN PEDRO DE MACORIS-SAN PEDRO MACORIS-SAN PEDRO DE MACORIS-hatos de san pedro-1ra-27-EDF Angela-4B-entrando por donde jocesito-C-8296950870-0-C-8297635918-0-C-0-0 | M31: SAN PEDRO DE MACORIS | N31: SAN PEDRO MACORIS | O31: SAN PEDRO DE MACORIS | P31: hatos de san pedro | Q31: 1ra | R31: 27 | S31: EDF Angela | T31: 4B | U31: entrando por donde jocesito | V31: C | W31: 8296950870 | X31: 0 | Y31: C | Z31: 8297635918 | AA31: 0 | AB31: C | AC31: 0 | AD31: 0 | AE31: 45883.54 | AG31: TD- ENTREGADO
A32: 45883 | B32: 4-12189026642 | C32: 45883 | D32: PAMELA MARTINEZ URENA | E32: =VLOOKUP(DataOld!$B32,DATA!B:H,7,FALSE) -> #N/A | F32: =DataOld!$D32=DataOld!$E32 -> #N/A | G32: =VLOOKUP(DataOld!$B32,DATA!B:G,6,FALSE) -> #N/A | H32: 40209123575 | I32: =DataOld!$H32=DataOld!$G32 -> #N/A | J32: Centro Digital Popular | K32: SANTIAGO;SANTIAGO;Arenoso | L32: Santiago-Santiago-Santiago-Arenoso-Calle los Rodriguez -56-0-0-Por la escuela Joseflores-C-8095048161-0-C-8099942885-0-0-0 | M32: SANTIAGO | N32: SANTIAGO | O32: SANTIAGO | P32: Arenoso | Q32: Calle los Rodriguez | R32: 56 | S32: 0 | T32: 0 | U32: Por la escuela Joseflores | V32: C | W32: 8095048161 | X32: 0 | Y32: C | Z32: 8099942885 | AA32: 0 | AB32: 0 | AC32: 0 | AE32: 45883.602 | AG32: TD- RETIRADA EN OFICINA | AH32: CLIENTA INDICO QUE DESEARIA PASAR POR EL BANCO! | AL32: 8099942885 # ES DE NICOLLE SU HERMANA LA CUAL LA VA A RECIBIR Y ME ENVIARA LA UB POR WSS / UBICACION ENVIADA
A33: 45883 | B33: 4-12189115662 | C33: 45883 | D33: JEAN LUIS ENCARNACION BAEZ | E33: =VLOOKUP(DataOld!$B33,DATA!B:H,7,FALSE) -> #N/A | F33: =DataOld!$D33=DataOld!$E33 -> #N/A | G33: =VLOOKUP(DataOld!$B33,DATA!B:G,6,FALSE) -> #N/A | H33: 40206066581 | I33: =DataOld!$H33=DataOld!$G33 -> #N/A | J33: Centro Digital Popular | K33: SANTIAGO;SANTIAGO;Cerro alto | L33: Santiago-Santiago-Santiago-Cerro alto-Calle B-20-Reaidencial Polanco -202B-La misma Calle del Colegio -C-8492725586-0-C-8096263946-0-0-0 | M33: SANTIAGO | N33: SANTIAGO | O33: SANTIAGO | P33: Cerro alto | Q33: Calle B | R33: 20 | S33: Reaidencial Polanco | T33: 202B | U33: La misma Calle del Colegio | V33: C | W33: 8492725586 | X33: 0 | Y33: C | Z33: 8096263946 | AA33: 0 | AB33: 0 | AC33: 0 | AE33: 45883.611 | AG33: TD- ENTREGADO
A34: 45883 | B34: 4-12187803972 | C34: 45883 | D34: ENMANUEL ALEXANDER PEREZ VARGAS | E34: =VLOOKUP(DataOld!$B34,DATA!B:H,7,FALSE) -> #N/A | F34: =DataOld!$D34=DataOld!$E34 -> #N/A | G34: =VLOOKUP(DataOld!$B34,DATA!B:G,6,FALSE) -> #N/A | H34: 40208835823 | I34: =DataOld!$H34=DataOld!$G34 -> #N/A | J34: 242-OFICINA LAS COLINAS, STGO. | K34: SANTIAGO;SANTIAGO;padre las casas | L34: SANTIAGO-SANTIAGO-SANTIAGO-padre las casas-penetracion-91-castro-1-llamar-C-8498169462-0-C-8492075174-0-C-0-0 | M34: SANTIAGO | N34: SANTIAGO | O34: SANTIAGO | P34: padre las casas | Q34: penetracion | R34: 91 | S34: castro | T34: 1 | U34: llamar | V34: C | W34: 8498169462 | X34: 0 | Y34: C | Z34: 8492075174 | AA34: 0 | AB34: C | AC34: 0 | AD34: 0 | AE34: 45883.497 | AG34: TD- ENTREGADO
A35: 45883 | B35: 4-12187539232 | C35: 45883 | D35: MAXIMO JAVIER HIRALDO DE LEON | E35: =VLOOKUP(DataOld!$B35,DATA!B:H,7,FALSE) -> #N/A | F35: =DataOld!$D35=DataOld!$E35 -> #N/A | G35: =VLOOKUP(DataOld!$B35,DATA!B:G,6,FALSE) -> #N/A | H35: 40211009481 | I35: =DataOld!$H35=DataOld!$G35 -> #N/A | J35: 246-OFICINA ZONA FRANCA, STGO. | K35: SANTIAGO;SANTIAGO;Santiago | L35: Santiago-Santiago-Santiago-Santiago -Principal -1-Tabacalera fuente -Lingstica-Arturo fuente -C-8293597287-0-C-8292136769-0-0-0 | M35: SANTIAGO | N35: SANTIAGO | O35: SANTIAGO | P35: Santiago | Q35: Principal | R35: 1 | S35: Tabacalera fuente | T35: Lingstica | U35: Arturo fuente | V35: C | W35: 8293597287 | X35: 0 | Y35: C | Z35: 8292136769 | AA35: 0 | AB35: 0 | AC35: 0 | AE35: 45883.518 | AG35: TD- ENTREGADO
A36: 45883 | B36: 4-12189180822 | C36: 45883 | D36: LUZ YAMEL CRUZ GERMAN | E36: =VLOOKUP(DataOld!$B36,DATA!B:H,7,FALSE) -> #N/A | F36: =DataOld!$D36=DataOld!$E36 -> #N/A | G36: =VLOOKUP(DataOld!$B36,DATA!B:G,6,FALSE) -> #N/A | H36: 40210388100 | I36: =DataOld!$H36=DataOld!$G36 -> #N/A | J36: 464-OCCIDENTALL MALL | K36: SANTO DOMINGO;SANTO DOMINGO OESTE;San Miguel | L36: Santo Domingo-Santo Domingo Oeste-Santo Domingo Oeste-San Miguel -Antonia Perez -20-0-0-Entrar por el colmado angel -C-8097853359-0-C-8296011322-0-0-0 | M36: SANTO DOMINGO | N36: SANTO DOMINGO OESTE | O36: SANTO DOMINGO OESTE | P36: San Miguel | Q36: Antonia Perez | R36: 20 | S36: 0 | T36: 0 | U36: Entrar por el colmado angel | V36: C | W36: 8097853359 | X36: 0 | Y36: C | Z36: 8296011322 | AA36: 0 | AB36: 0 | AC36: 0 | AE36: 45883.619 | AG36: TD- ENTREGADO
A37: 45883 | B37: 4-12187853772 | C37: 45883 | D37: OSVALDO SAMUEL TURBI VALDEZ | E37: =VLOOKUP(DataOld!$B37,DATA!B:H,7,FALSE) -> #N/A | F37: =DataOld!$D37=DataOld!$E37 -> #N/A | G37: =VLOOKUP(DataOld!$B37,DATA!B:G,6,FALSE) -> #N/A | H37: 40225004999 | I37: =DataOld!$H37=DataOld!$G37 -> #N/A | J37: 317-OFICINA CARREFOUR | K37: SANTO DOMINGO;SANTO DOMINGO OESTE;Pantoja | L37: SANTO DOMINGO-SANTO DOMINGO OESTE-SANTO DOMINGO OESTE-Pantoja-Don Gregorio 3 Man A-41-0-0-Entrando por el Ayuntamiento-C-8298177792-0-C-8494597792-0-C-0-0 | M37: SANTO DOMINGO | N37: SANTO DOMINGO OESTE | O37: SANTO DOMINGO OESTE | P37: Pantoja | Q37: Don Gregorio 3 Man A | R37: 41 | S37: 0 | T37: 0 | U37: Entrando por el Ayuntamiento | V37: C | W37: 8298177792 | X37: 0 | Y37: C | Z37: 8494597792 | AA37: 0 | AB37: C | AC37: 0 | AD37: 0 | AE37: 45883.5 | AG37: TD- ENTREGADO
A38: 45883 | B38: 4-12188043972 | C38: 45883 | D38: ADAMS ISMAEL ACEVEDO POLANCO | E38: =VLOOKUP(DataOld!$B38,DATA!B:H,7,FALSE) -> #N/A | F38: =DataOld!$D38=DataOld!$E38 -> #N/A | G38: =VLOOKUP(DataOld!$B38,DATA!B:G,6,FALSE) -> #N/A | H38: 40202043351 | I38: =DataOld!$H38=DataOld!$G38 -> #N/A | J38: 383-OFICINA JUMBO LUPERON | K38: SANTO DOMINGO;LOS ALCARRIZOS;barrio 24 de abril | L38: SANTO DOMINGO-LOS ALCARRIZOS-LOS ALCARRIZOS-barrio 24 de abril-calle 2 casa 24-24-0-0-alcarrizos cerca de la duart-C-8099755492-0-C-8097200939-0-C-0-0 | M38: SANTO DOMINGO | N38: LOS ALCARRIZOS | O38: LOS ALCARRIZOS | P38: barrio 24 de abril | Q38: calle 2 casa 24 | R38: 24 | S38: 0 | T38: 0 | U38: alcarrizos cerca de la duart | V38: C | W38: 8099755492 | X38: 0 | Y38: C | Z38: 8097200939 | AA38: 0 | AB38: C | AC38: 0 | AD38: 0 | AE38: 45883.516 | AG38: TD- ENTREGADO
A39: 45883 | B39: 4-12187835962 | C39: 45883 | D39: YERALDIN MILIANO DE ARIAS | E39: =VLOOKUP(DataOld!$B39,DATA!B:H,7,FALSE) -> #N/A | F39: =DataOld!$D39=DataOld!$E39 -> #N/A | G39: =VLOOKUP(DataOld!$B39,DATA!B:G,6,FALSE) -> #N/A | H39: 06800508688 | I39: =DataOld!$H39=DataOld!$G39 -> #N/A | J39: 256-OFICINA BONAO | K39: SANTO DOMINGO;PEDRO BRAND;La guayiga | L39: Santo Domingo-Pedro Brand-Pedro Brand-La guayiga-Autopista Duarte Km -13-Arion Dominicana-Recepcin-Frente Res Pablo Mella-C-8099965543-0-T-8093383747-0000-0-0 | M39: SANTO DOMINGO | N39: PEDRO BRAND | O39: PEDRO BRAND | P39: La guayiga | Q39: Autopista Duarte Km | R39: 13 | S39: Arion Dominicana | T39: Recepcin | U39: Frente Res Pablo Mella | V39: C | W39: 8099965543 | X39: 0 | Y39: T | Z39: 8093383747 | AA39: 0000 | AB39: 0 | AC39: 0 | AE39: 45883.496 | AG39: TD- ENTREGADO
A40: 45883 | B40: 4-12189114782 | C40: 45883 | D40: JOSE MIGUEL CAMPUSANO ARIAS | E40: =VLOOKUP(DataOld!$B40,DATA!B:H,7,FALSE) -> #N/A | F40: =DataOld!$D40=DataOld!$E40 -> #N/A | G40: =VLOOKUP(DataOld!$B40,DATA!B:G,6,FALSE) -> #N/A | H40: 00119318913 | I40: =DataOld!$H40=DataOld!$G40 -> #N/A | J40: 140-OFICINA EL PORTAL | K40: SANTO DOMINGO;PEDRO BRAND;parque industrial | L40: SANTO DOMINGO-PEDRO BRAND-PEDRO BRAND-parque industrial-duarte-2-frito lay-logistica-mixing center-C-8498158576-0-T-8492483608-0-C-0-0 | M40: SANTO DOMINGO | N40: PEDRO BRAND | O40: PEDRO BRAND | P40: parque industrial | Q40: duarte | R40: 2 | S40: frito lay | T40: logistica | U40: mixing center | V40: C | W40: 8498158576 | X40: 0 | Y40: T | Z40: 8492483608 | AA40: 0 | AB40: C | AC40: 0 | AD40: 0 | AE40: 45883.611 | AG40: TD- ENTREGADO
...

Sheet Sheet1
A1: FECH ASIG | B1: (All)
A3: Row Labels | B3: Count of ESTATUS
A4: TD- DEVUELTO NO LOCALIZADO | B4: 7
A5: TD- ENTREGADO | B5: 684
A6: EN RUTA | B6: 45
A7: NO LOCALIZADA | B7: 8
A8: Grand Total | B8: 744
A21: Count of ESTATUS | B21: Column Labels
A22: Row Labels | B22: EN RUTA | C22: NO LOCALIZADA | D22: Grand Total
A23: 45922 | B23: 2 | D23: 2
A24: 45925 | B24: 5 | C24: 5 | D24: 10
A25: 45926 | B25: 2 | C25: 1 | D25: 3
A26: 45927 | B26: 4 | D26: 4
A27: 45929 | B27: 5 | C27: 2 | D27: 7
A28: 45930 | B28: 27 | D28: 27
A29: Grand Total | B29: 45 | C29: 8 | D29: 53

Sheet DATA
A1: FECH ASIG | B1: N-SS | C1: TIPO | D1: AREA | E1: SUBAREA | F1: ANALISTA_ASIGNADO | G1: NRO_ID | H1: CONTACTO | I1: NOMBRE_DE_OFICINA | J1: OFICIAL | K1: PROVMUNSEC | L1: DESCRIPCION_AMPLIADA | M1: PROVINCIA | N1: ESTADO | O1: DISTRITO_MUNICIPIAL | P1: SECTOR | Q1: CALLE | R1: NUMERO | S1: EMPRESA_EDIFICIO | T1: DEPTO_APTO | U1: REFERENCIA | V1: TIPO_TEL_1 | W1: TEL_1 | X1: EXT_TEL_1 | Y1: TIPO_TEL_2 | Z1: TEL_2 | AA1: EXT_TEL_2 | AB1: TIPO_TEL_3 | AC1: TEL_3 | AD1: EXT_TEL_3 | AE1: CREADO_POR | AF1: FECHA_CREACION | AG1: ZONA | AH1: STATUS | AI1: COMENTARIO | AJ1: QUIEN RECIBE | AK1: INFO TERCERO | AL1: FECHA DE ENTREGA | AM1: Comentario BPD | AN1: AREAS REMOTAS | AO1: Status Cc | AP1: Contacto Cc | AQ1: No. Contact
A2: 46204 | B2: 4-13794643002 | C2: Cuentas | D2: Solicitud de Servicios | E2: Entrega Tarjeta Debito | F2: U52123 | G2: 05600054539 | H2: NURYS JULISSA ABREU TAVAREZ | I2: 243-OFICINA CALLE DEL SOL, STGO. | J2: U32288 | K2: Santiago;Santiago;Fernndez | L2: Santiago-Santiago-Santiago-Fernndez-Circunvalacion -202-Funpisa-202-Supermercado-C-8092515808-0-C-8298561307-0-T-8092417771-0 | M2: Santiago | N2: Santiago | O2: Santiago | P2: Fernndez | Q2: Circunvalacion | R2: 202 | S2: Funpisa | T2: 202 | U2: Supermercado | V2: C | W2: 8092515808 | X2: 0 | Y2: C | Z2: 8298561307 | AA2: 0 | AB2: T | AC2: 8092417771 | AD2: 0 | AE2: APPPOPULAR | AF2: 46203.679 | AG2: En proceso | AH2: TD- ENTREGADO | AJ2: PRINCIPAL | AL2: 46209 | AO2: Contactos Efectivos | AP2: ENVIO A DIRECCION AL CLIENTE !NPROVINCIA// SANTIANGO DE LOS CABALLEROS !NEMPRESA// VILLA OLIMPICA !NSECTOR// FUNPISA !NCALLE // AV CINCUNVALACION !NDEP// SERVICIO !NREFE// DENTRO DE LA PLAZA FERNANDEZ AL LADO DE SUPERMERCADO LA FUENTE !NTELL/HORA 8092515808 8 AM A 5 PM !NKCRUZ!N!N | AQ2: 8092515808
A3: 46204 | B3: 4-13800808542 | C3: Cuentas | D3: Solicitud de Servicios | E3: Entrega Tarjeta Debito | F3: U52123 | G3: 40224078192 | H3: CRISMARY JIMENEZ GUZMAN | I3: 253-OFICINA PUERTO PLATA | J3: U39793 | K3: Puerto Plata;Sosua;El choco | L3: Puerto Plata-Sosua-Sosua-El choco-Carretera el choco-0-Casa linda-Arq-Arquitectura -C-8295521220-0-T-8095711190-221-0-0 | M3: Puerto Plata | N3: Sosua | O3: Sosua | P3: El choco | Q3: Carretera el choco | R3: 0 | S3: Casa linda | T3: arq | U3: Arquitectura | V3: C | W3: 8295521220 | X3: 0 | Y3: T | Z3: 8095711190 | AA3: 221 | AB3: 0 | AC3: 0 | AE3: APPPOPULAR | AF3: 46204.54 | AG3: En proceso | AH3: TD- ENTREGADO | AJ3: PRINCIPAL | AL3: 46216 | AN3: SI | AO3: Contactos Efectivos | AP3: POERTO PLATA//SOSUA!NCALLE CARRE EL CHOCO !NResidencial Casa Linda!NDP// Arquitectura !NREF/Sosua Ocean Village!N8295521220 HORA 8 A 5 !NJRAMOS | AQ3: 8295521220
A4: 46204 | B4: 4-13798526962 | C4: Cuentas | D4: Solicitud de Servicios | E4: Entrega Tarjeta Debito | F4: U52123 | G4: 03200219420 | H4: MIGUELINA SANTANA RAMOS | I4: 246-OFICINA ZONA FRANCA, STGO. | J4: U35634 | K4: SANTIAGO;SANTIAGO;ZonaFrancaIndustrial | L4: SANTIAGO-SANTIAGO-SANTIAGO-ZonaFrancaIndustrial-Av Longitudinal-28-Eaton Aerospace Souriau-Servicio-2da Etapa cerca Los Bomberos-C-8099033339-0-T-8096252000-0-C-0-0 | M4: Santiago | N4: Santiago | O4: Santiago | P4: ZonaFrancaIndustrial | Q4: Av longitudinal | R4: 28 | S4: Eaton Aerospace Souriau | T4: Servicio | U4: 2da Etapa cerca Los Bomberos | V4: C | W4: 8099033339 | X4: 0 | Y4: T | Z4: 8096252000 | AA4: 0 | AB4: C | AC4: 0 | AD4: 0 | AE4: APPPOPULAR | AF4: 46204.414 | AG4: En proceso | AH4: TD- ENTREGADO | AJ4: PRINCIPAL | AL4: 46209 | AO4: Contactos Efectivos | AP4: ENVIAR A DIRECCION CLIENTE!NOGUTIERREZ!N!NSANTIAGO!NSECT//ZONA FRANCA INDUSTRIAL!NCALLE//AV LONGITUDINAL NO 28!NEMPRESAS//EATON AEROSPACCE SOURIAU!NDEP//SERVICIO !NREF// PROXIMO A LOS BOMBEROS !N8099033339 HORA 8AM A 5PM !NDISPONIBLE EL LUNES | AQ4: 8099033339
A5: 46205 | B5: 4-13806004192 | C5: Cuentas | D5: Solicitud de Servicios | E5: Entrega Tarjeta Debito | F5: U52123 | G5: 03101913196 | H5: MARIA ANTONIA DE JESUS MUESES E DE CANAHUAT | I5: 244-OFICINA 27 DE FEBRERO, STGO. | J5: U19099 | K5: Santiago;Santiago;Los jardines | L5: SANTIAGO-SANTIAGO-SANTIAGO-Los Jardines-Aquiles Ramirez-17-0-0-Cancha CDP-C-8096961118-0-R-8095826834-0-C-8096961119-0 | M5: Santiago | N5: Santiago | O5: Santiago | P5: Los jardines | Q5: Aquiles Ramirez | R5: 17 | S5: 0 | T5: 0 | U5: Cancha CDP | V5: C | W5: 8096961118 | X5: 0 | Y5: R | Z5: 8095826834 | AA5: 0 | AB5: C | AC5: 8096961119 | AD5: 0 | AE5: APPPOPULAR | AF5: 46205.319 | AG5: En proceso | AH5: TD- ENTREGADO | AJ5: PRINCIPAL | AL5: 46210 | AO5: Contactos Efectivos | AP5: SATIAGO !NLOS JARDINES METROPOLITANOS !NCALLE AQUILES RAMIREZ !NCASA NO 17!NPROX AL CLUB DOMINGO PAULINO !N8096961118 HORA 3PM A 5PM !NAOGANDO | AQ5: 8096961118
A6: 46205 | B6: 4-13805664032 | C6: Cuentas | D6: Solicitud de Servicios | E6: Entrega Tarjeta Debito | F6: U52123 | G6: 03105743565 | H6: RAILYN ISMAEL PAULINO BALBUENA | I6: 458-OFICINA MULTICENTRO LA SIRENA EL EMBRUJO STGO | J6: U22429 | K6: Santiago;Santiago;Hato del Yaque | L6: Santiago-Santiago-Santiago-Hato Del Yaque-La Paz -40-0-0-Estudio de grabacin-C-8299804858-0-C-8299804852-0-0-0 | M6: Santiago | N6: Santiago | O6: Santiago | P6: Hato del Yaque | Q6: la paz | R6: 40 | S6: 0 | T6: 0 | U6: Estudio de grabacin | V6: C | W6: 8299804858 | X6: 0 | Y6: C | Z6: 8299804852 | AA6: 0 | AB6: 0 | AC6: 0 | AE6: APPPOPULAR | AF6: 46204.992 | AG6: En proceso | AH6: TD- DEVUELTO NO LOCALIZADO | AI6: no responde ws ni llamadas | AJ6: PRINCIPAL
A7: 46205 | B7: 4-13802824452 | C7: Cuentas | D7: Solicitud de Servicios | E7: Entrega Tarjeta Debito | F7: U46603 | G7: 40212318824 | H7: EMELY MELISSA PICHARDO CASTILLO | I7: OFICINA DOWNTOWN CENTER MALL | K7: Santiago;Santiago;Arroyo hondo abajo | L7: SANTIAGO-SANTIAGO-SANTIAGO-ARROYO HONDO ABAJO-MARIA TRINIDAD SANCHEZ-17-0-0-AL LADO DE COLMADO MARLIN -C-8297523579-0-T-8494288039- | M7: Santiago | N7: Santiago | O7: Santiago | P7: Arroyo hondo abajo | Q7: Maria trinidad sanch | R7: 17 | S7: 0 | T7: 0 | U7: AL LADO DE COLMADO MARLIN | V7: C | W7: 8297523579 | X7: 0 | Y7: T | Z7: 8494288039 | AE7: APPPOPULAR | AF7: 46204.636 | AG7: En proceso | AH7: TD- ENTREGADO | AJ7: PRINCIPAL | AL7: 46209 | AO7: Contactos Efectivos | AP7: ENVIO A DIRECCION AL CLIENTE !NPROVINCIA//SANTIAGO DE CABALLEROS !NSECTOR// ARROYO HONDO ABAJO !NREFE// AL LADO DE COLMADO MARLIN!NCALLE// MARIA TRINIDAD SANCHEZ NO 17!NTELL//HORA 8297523579 8 AM A 5 PM !NRECIBIRA// MELISSA!NKCRUZ!N | AQ7: 8297523579
A8: 46205 | B8: 4-13805672272 | C8: Cuentas | D8: Solicitud de Servicios | E8: Entrega Tarjeta Debito | F8: U52123 | G8: 40218265987 | H8: ROIDANYS DE LOS SANTOS CRUZ | I8: 245-OFICINA RESTAURACION | J8: U38516 | K8: Santiago;Santiago;Hato del Yaque | L8: Santiago-Santiago-Santiago-Hato del Yaque -Calle 7 la mina -56-0-0-Por el taller de Fili-C-8493952210-0-C-8494097927-0-0-0 | M8: Santiago | N8: Santiago | O8: Santiago | P8: Hato del Yaque | Q8: Calle 7 la mina | R8: 56 | S8: 0 | T8: 0 | U8: Por el taller de Fili | V8: C | W8: 8493952210 | X8: 0 | Y8: C | Z8: 8494097927 | AA8: 0 | AB8: 0 | AC8: 0 | AE8: APPPOPULAR | AF8: 46204.958 | AG8: En proceso | AH8: TD- ENTREGADO | AJ8: PRINCIPAL | AL8: 46210
A9: 46205 | B9: 4-13805247502 | C9: Cuentas | D9: Solicitud de Servicios | E9: Entrega Tarjeta Debito | F9: U46603 | G9: 40215703063 | H9: CESAR LEONCIO REYES MEJIA | I9: OFICINA DOWNTOWN CENTER MALL | K9: Santiago;Santiago;Mejoramiento social | L9: SANTIAGO-SANTIAGO-SANTIAGO-MEJORAMIENTO SOCIAL-LA FUENTE CASA-16-0-0-DENISES-C-8294909466-0-C-8494487694-0 | M9: Santiago | N9: Santiago | O9: Santiago | P9: Mejoramiento social | Q9: LA FUENTE CASA | R9: 16 | S9: 0 | T9: 0 | U9: DENISES | V9: C | W9: 8294909466 | X9: 0 | Y9: C | Z9: 8494487694 | AA9: 0 | AE9: APPPOPULAR | AF9: 46204.822 | AG9: En proceso | AH9: TD- DEVUELTO NO LOCALIZADO | AJ9: PRINCIPAL
A10: 46205 | B10: 4-13809606032 | C10: Cuentas | D10: Solicitud de Servicios | E10: Entrega Tarjeta Debito | F10: APPPOPULAR | G10: 03105181071 | H10: ANTHONY DE JESUS HERNANDEZ ESTEVEZ | I10: 259-OFICINA UTESA, SANTIAGO | J10: U37650 | K10: Santiago;Santiago;Ensanche Espaillat | L10: SANTIAGO-SANTIAGO-SANTIAGO-ensanche espaillat-12-78-0-0-0-C-8492200921-0-C-8297262494-0-C-0-0 | M10: SANTIAGO | N10: Santiago | O10: Santiago | P10: Ensanche Espaillat | Q10: 12 | R10: 78 | S10: 0 | T10: 0 | U10: 0 | V10: C | W10: 8492200921 | X10: 0 | Y10: C | Z10: 8297262494 | AA10: 0 | AB10: C | AC10: 0 | AD10: 0 | AE10: APPPOPULAR | AF10: 46205.551 | AG10: En proceso | AH10: TD- ENTREGADO | AJ10: PRINCIPAL | AL10: 46209
A11: 46205 | B11: 4-13809476302 | C11: Cuentas | D11: Solicitud de Servicios | E11: Entrega Tarjeta Debito | F11: APPPOPULAR | G11: 40230381366 | H11: PABLO DANIEL PEREZ ROSA | I11: 199-OFICINA DUARTE | J11: U41438 | K11: SANTIAGO;BISONO;MINERVA O SIMON BOLI | L11: SANTIAGO-BISONO-BISONO-MINERVA O SIMON BOLIVAR-LAS AMERCA CASA--0-0-0-C-8295322044-0-C-8494318168-0 | M11: SANTIAGO | N11: Bisono | O11: Bisono | P11: MINERVA O SIMON BOLI | Q11: LAS AMERCA CASA | S11: 0 | T11: 0 | U11: 0 | V11: C | W11: 8295322044 | X11: 0 | Y11: C | Z11: 8494318168 | AA11: 0 | AE11: APPPOPULAR | AF11: 46205.533 | AG11: En proceso | AH11: TD- ENTREGADO | AI11: Josue | AJ11: PRINCIPAL | AK11: Josue | AL11: 46218 | AN11: SI
A12: 46206 | B12: 4-13813809882 | C12: Cuentas | D12: Solicitud de Servicios | E12: Entrega Tarjeta Debito | F12: U46603 | G12: 03103439901 | H12: CARMEN ALEJANDRINA DELGADO RAMOS | I12: 243-OFICINA CALLE DEL SOL, STGO. | J12: U46454 | K12: Santiago;Santiago;La Rosaleda | L12: SANTIAGO-SANTIAGO-SANTIAGO-La Rosaleda-Juan Lockward-5-Edificio GVVI-C1-Cerca Cine Hollywood-C-8098201516-0-R-8099712341-0-C-0-0 | M12: Santiago | N12: Santiago | O12: Santiago | P12: La Rosaleda | Q12: Juan Lockward | R12: 5 | S12: Edificio GVVI | T12: C1 | U12: Cerca Cine Hollywood | V12: C | W12: 8098201516 | X12: 0 | Y12: R | Z12: 8099712341 | AA12: 0 | AB12: C | AC12: 0 | AD12: 0 | AE12: APPPOPULAR | AF12: 46206.287 | AG12: En proceso | AH12: TD- ENTREGADO | AJ12: PRINCIPAL | AL12: 46209
A13: 46206 | B13: 4-13813573252 | C13: Cuentas | D13: Solicitud de Servicios | E13: Entrega Tarjeta Debito | F13: U46603 | G13: 35000012985 | H13: JUAN ENMANUEL GUZMAN GUZMAN | I13: 458-OFICINA MULTICENTRO LA SIRENA EL EMBRUJO STGO | J13: U22429 | K13: Santiago;Santiago;Baracoa | L13: SANTIAGO-SANTIAGO-SANTIAGO-BARACOA-principal-11-0-0-Al lado de one tech-C-8494594908-0-R-8093951274-0 | M13: Santiago | N13: Santiago | O13: Santiago | P13: Baracoa | Q13: Principal | R13: 11 | S13: 0 | T13: 0 | U13: Al lado de one tech | V13: C | W13: 8494594908 | X13: 0 | Y13: R | Z13: 8093951274 | AA13: 0 | AE13: APPPOPULAR | AF13: 46205.96 | AG13: En proceso | AH13: TD- ENTREGADO | AJ13: PRINCIPAL | AL13: 46209
A14: 46206 | B14: 4-13813346882 | C14: Cuentas | D14: Solicitud de Servicios | E14: Entrega Tarjeta Debito | F14: U52123 | G14: 40219093172 | H14: NOELIA RAQUEL CASTANEDA SANTIAGO | I14: 349-OFICINA SANTIAGO CENTER | J14: U40202 | K14: Santiago;Santiago;Yapurt Dumit | L14: Santiago-Santiago-Santiago-Yapurt dumit -Margarita-0-Casa crema con blanco -Casa 36-Al lado del hospital hemmi-C-8092145237-0-C-8092191453-0-0-0 | M14: Santiago | N14: Santiago | O14: Santiago | P14: Yapurt Dumit | Q14: Margarita | R14: 0 | S14: Casa crema con blanco | T14: Casa 36 | U14: Al lado del hospital hemmi | V14: C | W14: 8092145237 | X14: 0 | Y14: C | Z14: 8092191453 | AA14: 0 | AB14: 0 | AC14: 0 | AE14: APPPOPULAR | AF14: 46205.899 | AG14: En proceso | AH14: TD- ENTREGADO | AJ14: PRINCIPAL | AL14: 46209
A15: 46206 | B15: 4-13811310822 | C15: Cuentas | D15: Solicitud de Servicios | E15: Entrega Tarjeta Debito | F15: APPPOPULAR | G15: 40220154260 | H15: GINNETTE LOUISE BENOIT CABRERA | I15: 246-OFICINA ZONA FRANCA, STGO. | J15: U38309 | K15: Santiago;Santiago;Los salados viejos | L15: Santiago-Santiago-Santiago-Los salados viejos -15 no 25-25-0-0-8092722170-C-8092722170-0-C-8297597471-0-0-0 | M15: Santiago | N15: Santiago | O15: Santiago | P15: Los salados viejos | Q15: 15 no 25 | R15: 25 | S15: 0 | T15: 0 | U15: 8092722170 | V15: C | W15: 8092722170 | X15: 0 | Y15: C | Z15: 8297597471 | AA15: 0 | AB15: 0 | AC15: 0 | AE15: APPPOPULAR | AF15: 46205.646 | AG15: En proceso | AH15: TD- ENTREGADO | AJ15: PRINCIPAL | AL15: 46210
A16: 46206 | B16: 4-13811370422 | C16: Cuentas | D16: Solicitud de Servicios | E16: Entrega Tarjeta Debito | F16: APPPOPULAR | G16: 40225954995 | H16: GENESIS VILLANUEVA | I16: 135-OFICINA TORRE POPULAR | J16: U24107 | K16: Santiago;Santiago;Valle Verde 1 | L16: Santiago-Santiago-Santiago-Valle Verde 1 -Calle 8-15-0-0-0-C-8094205672-0-C-8099759239-0-0-0 | M16: Santiago | N16: Santiago | O16: Santiago | P16: Valle Verde 1 | Q16: Calle 8 | R16: 15 | S16: 0 | T16: 0 | U16: 0 | V16: C | W16: 8094205672 | X16: 0 | Y16: C | Z16: 8099759239 | AA16: 0 | AB16: 0 | AC16: 0 | AE16: APPPOPULAR | AF16: 46205.65 | AG16: En proceso | AH16: TD- ENTREGADO | AJ16: PRINCIPAL | AL16: 46227
A17: 46206 | B17: 4-13817129792 | C17: Cuentas | D17: Solicitud de Servicios | E17: Entrega Tarjeta Debito | F17: APPPOPULAR | G17: 40235504715 | H17: FAUSTINA DE LEON RAMON | I17: 246-OFICINA ZONA FRANCA, STGO. | J17: U50597 | K17: Santiago;Santiago;Mella 2 | L17: SANTIAGO-SANTIAGO-SANTIAGO-mella 2-6-2-ensima del colmado gonzal-2-ensima del colmado gonzales-C-8293901833-0-C-8294552092-0-C-0-0 | M17: Santiago | N17: Santiago | O17: Santiago | P17: Mella 2 | Q17: 6 | R17: 2 | S17: ensima del colmado gonzal | T17: 2 | U17: ensima del colmado gonzales | V17: C | W17: 8293901833 | X17: 0 | Y17: C | Z17: 8294552092 | AA17: 0 | AB17: C | AC17: 0 | AD17: 0 | AE17: APPPOPULAR | AF17: 46206.568 | AG17: En proceso | AH17: TD- ENTREGADO | AJ17: PRINCIPAL | AL17: 46210
A18: 46206 | B18: 4-13814200352 | C18: Cuentas | D18: Solicitud de Servicios | E18: Entrega Tarjeta Debito | F18: U46603 | G18: 40214722858 | H18: ENGER RODRIGUEZ | I18: 290-OFICINA GURABO | J18: U43122 | K18: Santiago;Santiago;Bella vista | L18: Santiago-Santiago-Santiago-Bella vista-Calle marginal -3-Apto A3-A3-Arriba de tienda camalenjea-C-8494480110-0-C-8092010524-0-0-0 | M18: Santiago | N18: Santiago | O18: Santiago | P18: Bella vista | Q18: Calle marginal | R18: 3 | S18: Apto A3 | T18: A3 | U18: Arriba de tienda camalenjea | V18: C | W18: 8494480110 | X18: 0 | Y18: C | Z18: 8092010524 | AA18: 0 | AB18: 0 | AC18: 0 | AE18: APPPOPULAR | AF18: 46206.387 | AG18: En proceso | AH18: TD- ENTREGADO | AJ18: PRINCIPAL | AL18: 46209
A19: 46204 | B19: 4-13796626732 | C19: Cuentas | D19: Solicitud de Servicios | E19: Entrega Tarjeta Debito | F19: U52123 | G19: 40212883371 | H19: SMAILY REYES ROSARIO | I19: OFICINA DOWNTOWN CENTER MALL | K19: DISTRITO NACIONAL;SANTO DOMINGO;los Alcarrizos klm14 | L19: DISTRITO NACIONAL-SANTO DOMINGO-SANTO DOMINGO DE GUZMAN-los Alcarrizos klm14-calle los triste-01-0-0-después del mocano mofongo-C-8296493323-0-C-8098693622-0-C-0-0 | M19: Distrito Nacional | N19: Santo Domingo | O19: Santo Domingo De Guzman | P19: los Alcarrizos klm14 | Q19: calle los triste | R19: 01 | S19: 0 | T19: 0 | U19: después del mocano mofongo | V19: C | W19: 8296493323 | X19: 0 | Y19: C | Z19: 8098693622 | AA19: 0 | AB19: C | AC19: 0 | AD19: 0 | AE19: APPPOPULAR | AF19: 46203.879 | AG19: En proceso | AH19: TD- ENTREGADO | AI19: Charina Mendez | AJ19: PRINCIPAL | AL19: 46205
A20: 46204 | B20: 4-13796292932 | C20: Cuentas | D20: Solicitud de Servicios | E20: Entrega Tarjeta Debito | F20: U52123 | G20: 40200476733 | H20: JESSICA MARIEL DE LA HOZ NUNEZ | I20: 142-OFICINA NUÑEZ DE CACERES | J20: U30387 | K20: Distrito Nacional;Santo Domingo;Los alcarrizos | L20: Distrito Nacional-Santo Domingo-Santo Domingo De Guzman-Los alcarrizos -Calle triste -1-Mercatodo -Recepcin-Detrs de Agroindustrial-C-8296901595-0-C-8099731605-0-0-0 | M20: Distrito Nacional | N20: Santo Domingo | O20: Santo Domingo De Guzman | P20: Los alcarrizos | Q20: Calle triste | R20: 1 | S20: Mercatodo | T20: Recepcin | U20: Detrs de Agroindustrial | V20: C | W20: 8296901595 | X20: 0 | Y20: C | Z20: 8099731605 | AA20: 0 | AB20: 0 | AC20: 0 | AE20: APPPOPULAR | AF20: 46203.854 | AG20: En proceso | AH20: TD- ENTREGADO | AI20: Charina Mendez | AJ20: PRINCIPAL | AL20: 46205
A21: 46209 | B21: 4-13823892552 | C21: Cuentas | D21: Solicitud de Servicios | E21: Entrega Tarjeta Debito | F21: APPPOPULAR | G21: 40255006179 | H21: ENMANUEL GONZALEZ FERRERAS | I21: 246-OFICINA ZONA FRANCA, STGO. | J21: U38309 | K21: Santiago;Santiago;Rafey | L21: Santiago-Santiago-Santiago-Rafey-Calle Central 3 -3-Sewn product inc -almacn-0-C-8093912203-0-C-8297200948-0-0-0 | M21: Santiago | N21: Santiago | O21: Santiago | P21: Rafey | Q21: Calle Central 3 | R21: 3 | S21: Sewn product inc | T21: Almacn | U21: 0 | V21: C | W21: 8093912203 | X21: 0 | Y21: C | Z21: 8297200948 | AA21: 0 | AB21: 0 | AC21: 0 | AE21: APPPOPULAR | AF21: 46208.882 | AG21: En proceso | AH21: TD- ENTREGADO | AI21: Posiblemente entregada | AJ21: PRINCIPAL | AL21: 46218
A22: 46209 | B22: 4-13823928972 | C22: Cuentas | D22: Solicitud de Servicios | E22: Entrega Tarjeta Debito | F22: APPPOPULAR | G22: 40209968730 | H22: YOSELIN DE LA ROSA DE AZA | I22: 246-OFICINA ZONA FRANCA, STGO. | J22: U45679 | K22: SANTIAGO;SANTIAGO;ensanche espallat | L22: SANTIAGO-SANTIAGO-SANTIAGO-ensanche espallat-10 esquina 8-56-0-0-0-C-8297124941-0-C-8298806674-0-C-0-0 | M22: Santiago | N22: Santiago | O22: Santiago | P22: ensanche espallat | Q22: 10 esquina 8 | R22: 56 | S22: 0 | T22: 0 | U22: 0 | V22: C | W22: 8297124941 | X22: 0 | Y22: C | Z22: 8298806674 | AA22: 0 | AB22: C | AC22: 0 | AD22: 0 | AE22: APPPOPULAR | AF22: 46208.718 | AG22: En proceso | AH22: TD- ENTREGADO | AJ22: PRINCIPAL | AL22: 46213
A23: 46209 | B23: 4-13823797392 | C23: Cuentas | D23: Solicitud de Servicios | E23: Entrega Tarjeta Debito | F23: APPPOPULAR | G23: 40218287643 | H23: ARGENIDY VASQUEZ GARCIA | I23: OFICINA DOWNTOWN CENTER MALL | K23: Santiago;Santiago;Ensanche libertad | L23: SANTIAGO-SANTIAGO-SANTIAGO-ENSANCHE LIBERTAD-VILLA ROSA 1 CALLE-6-0-0-METALERA RICARDO PISTA NUEVA -C-8292480942-0-C-8292948668-0 | M23: Santiago | N23: Santiago | O23: Santiago | P23: Ensanche libertad | Q23: VILLA ROSA 1 CALLE | R23: 6 | S23: 0 | T23: 0 | U23: METALERA RICARDO PISTA NUEVA | V23: C | W23: 8292480942 | X23: 0 | Y23: C | Z23: 8292948668 | AA23: 0 | AE23: APPPOPULAR | AF23: 46208.581 | AG23: En proceso | AH23: TD- ENTREGADO | AJ23: PRINCIPAL | AL23: 46213
A24: 46209 | B24: 4-13823739162 | C24: Cuentas | D24: Solicitud de Servicios | E24: Entrega Tarjeta Debito | F24: APPPOPULAR | G24: 00119476687 | H24: JORGE MANUEL LAUREANO | I24: OFICINA DOWNTOWN CENTER MALL | K24: SANTIAGO;SANTIAGO;ESPAILLAT | L24: SANTIAGO-SANTIAGO-SANTIAGO-ESPAILLAT-CENTRAL CASA-27-0-0-COMPRAVENTA FEDERICO-C-8094161920-0-C-8492807169-0 | M24: Santiago | N24: Santiago | O24: Santiago | P24: Espaillat | Q24: CENTRAL CASA | R24: 27 | S24: 0 | T24: 0 | U24: COMPRAVENTA FEDERICO | V24: C | W24: 8094161920 | X24: 0 | Y24: C | Z24: 8492807169 | AA24: 0 | AE24: APPPOPULAR | AF24: 46208.571 | AG24: En proceso | AH24: TD- ENTREGADO | AI24: Josue | AJ24: PRINCIPAL | AK24: Josue | AL24: 46223
A25: 46209 | B25: 4-13823734982 | C25: Cuentas | D25: Solicitud de Servicios | E25: Entrega Tarjeta Debito | F25: APPPOPULAR | G25: 40232829503 | H25: RICARDO ALFONSO MORA GARCIA | I25: OFICINA DOWNTOWN CENTER MALL | K25: Santiago;Santiago;Ensanche libertad | L25: SANTIAGO-SANTIAGO-SANTIAGO-ENSANCHE LIBERTAD-CASA 36 CALLE-13-0-0-METALERA RICARDO PISTA MUEVA-C-8292948668-0-C-8297122282-0 | M25: Santiago | N25: Santiago | O25: Santiago | P25: Ensanche libertad | Q25: CASA 36 CALLE | R25: 13 | S25: 0 | T25: 0 | U25: METALERA RICARDO PISTA MUEVA | V25: C | W25: 8292948668 | X25: 0 | Y25: C | Z25: 8297122282 | AA25: 0 | AE25: APPPOPULAR | AF25: 46208.555 | AG25: En proceso | AH25: TD- ENTREGADO | AJ25: PRINCIPAL | AL25: 46213
A26: 46209 | B26: 4-13823548252 | C26: Cuentas | D26: Solicitud de Servicios | E26: Entrega Tarjeta Debito | F26: APPPOPULAR | G26: 40204763094 | H26: DARLENYS MARIA ESPINO PEREZ | I26: OFICINA DOWNTOWN CENTER MALL | K26: Santiago;Santiago;Cerros de Gurabo | L26: Santiago-Santiago-Santiago-Cerros de gurabo-Av 27 de febrero-1-Mr Grilled-Mr GRILLED-Frente a los cerros de gurab-C-8496548184-0-T-8099713021-0-0-0 | M26: Santiago | N26: Santiago | O26: Santiago | P26: Cerros de Gurabo | Q26: Av 27 de febrero | R26: 1 | S26: Mr Grilled | T26: Mr GRILLED | U26: Frente a los cerros de gurab | V26: C | W26: 8496548184 | X26: 0 | Y26: T | Z26: 8099713021 | AA26: 0 | AB26: 0 | AC26: 0 | AE26: APPPOPULAR | AF26: 46208.348 | AG26: En proceso | AH26: TD- ENTREGADO | AJ26: PRINCIPAL | AL26: 46213
A27: 46209 | B27: 4-13823429012 | C27: Cuentas | D27: Solicitud de Servicios | E27: Entrega Tarjeta Debito | F27: APPPOPULAR | G27: 40237302605 | H27: RICHARD ENMANUEL PENA NIVAR | I27: 266-OFICINA AV. JUAN PABLO DUARTE | J27: U28485 | K27: Santiago;Santiago;Nibaje | L27: SANTIAGO-SANTIAGO-SANTIAGO-Nibaje-3-36-0-0-Cerca de Coraasan-C-8292898501-0-C-8096046979-0-C-0-0 | M27: Santiago | N27: Santiago | O27: Santiago | P27: Nibaje | Q27: 3 | R27: 36 | S27: 0 | T27: 0 | U27: Cerca de Coraasan | V27: C | W27: 8292898501 | X27: 0 | Y27: C | Z27: 8096046979 | AA27: 0 | AB27: C | AC27: 0 | AD27: 0 | AE27: APPPOPULAR | AF27: 46208.185 | AG27: En proceso | AH27: TD- ENTREGADO | AJ27: PRINCIPAL | AL27: 46212
A28: 46204 | B28: 4-13796423192 | C28: Cuentas | D28: Solicitud de Servicios | E28: Entrega Tarjeta Debito | F28: U52123 | G28: 02600166504 | H28: ROSELY MARTINEZ G DE BERGES | I28: SUCURSAL MULTIPLAZA LA ROMANA | J28: U22711 | K28: La Romana;La Romana;Romana del Oeste | L28: LA ROMANA-LA ROMANA-LA ROMANA-Romana del Oeste-10-42-0-0-detras del edificio Cristal-R-8095501665-0-T-8293447581-0-T-8094810717-0 | M28: La Romana | N28: LA ROMANA | O28: La Romana | P28: Romana del Oeste | Q28: 10 | R28: 42 | S28: 0 | T28: 0 | U28: detras del edificio Cristal | V28: R | W28: 8095501665 | X28: 0 | Y28: T | Z28: 8293447581 | AA28: 0 | AB28: T | AC28: 8094810717 | AD28: 0 | AE28: APPPOPULAR | AF28: 46203.93 | AG28: En proceso | AH28: TD- ENTREGADO | AJ28: PRINCIPAL | AL28: 46205
A29: 46204 | B29: 4-13796423072 | C29: Cuentas | D29: Solicitud de Servicios | E29: Entrega Tarjeta Debito | F29: U52123 | G29: 02601424076 | H29: JESSICA QUEZADA PEREZ | I29: 337-OFICINA HIPERJUMBO LA ROMANA | J29: U29844 | K29: La Romana;La Romana;Batey Principal | L29: La Romana-La Romana-La Romana-Batey Principal - primera-01-Central Romana -Compras-Frente hospital -C-8497524225-0-C-8498555617-0-0-0 | M29: La Romana | N29: LA ROMANA | O29: La Romana | P29: Batey Principal | Q29: Primera | R29: 01 | S29: Central Romana | T29: Compras | U29: Frente hospital | V29: C | W29: 8497524225 | X29: 0 | Y29: C | Z29: 8498555617 | AA29: 0 | AB29: 0 | AC29: 0 | AE29: APPPOPULAR | AF29: 46203.911 | AG29: En proceso | AH29: TD- ENTREGADO | AJ29: PRINCIPAL | AL29: 46204
A30: 46209 | B30: 4-13819149252 | C30: Cuentas | D30: Solicitud de Servicios | E30: Entrega Tarjeta Debito | F30: APPPOPULAR | G30: 03104823111 | H30: MARIELA LOPEZ SANTANA | I30: 290-OFICINA GURABO | J30: U24448 | K30: Santiago;Santiago;Llanos de Gurabo | L30: Santiago-Santiago-Santiago-Llanos de Gurabo-Calle 10 -0-RyL XV -F1-0-C-8098564742-0-C-8097103340-0-0-0 | M30: Santiago | N30: Santiago | O30: Santiago | P30: Llanos de Gurabo | Q30: Calle 10 | R30: 0 | S30: RyL XV | T30: F1 | U30: 0 | V30: C | W30: 8098564742 | X30: 0 | Y30: C | Z30: 8097103340 | AA30: 0 | AB30: 0 | AC30: 0 | AE30: APPPOPULAR | AF30: 46206.687 | AG30: En proceso | AH30: TD- ENTREGADO | AJ30: PRINCIPAL | AL30: 46213
A31: 46209 | B31: 4-13823180452 | C31: Cuentas | D31: Solicitud de Servicios | E31: Entrega Tarjeta Debito | F31: APPPOPULAR | G31: 03105419331 | H31: MICHEL NATALI LOPEZ GUZMAN | I31: MODELO PREFERENTE | J31: U35981 | K31: SANTIAGO;SANTIAGO;el paraiso | L31: SANTIAGO-SANTIAGO-SAN FRANCISCO DE JACAGUA-el paraiso-calle 8 casa 8-08-0-0-entrando por el puesto de ma-C-8492820062-0-C-8299904688-0-C-0-0 | M31: Santiago | N31: Santiago | O31: SAN FRANCISCO DE JACAGUA | P31: El Paraiso | Q31: calle 8 casa 8 | R31: 08 | S31: 0 | T31: 0 | U31: entrando por el puesto de ma | V31: C | W31: 8492820062 | X31: 0 | Y31: C | Z31: 8299904688 | AA31: 0 | AB31: C | AC31: 0 | AD31: 0 | AE31: APPPOPULAR | AF31: 46207.849 | AG31: En proceso | AH31: TD- ENTREGADO | AJ31: PRINCIPAL | AL31: 46213
A32: 46204 | B32: 4-13795808432 | C32: Cuentas | D32: Solicitud de Servicios | E32: Entrega Tarjeta Debito | F32: U52123 | G32: 40210326407 | H32: BRYANT CAPARROSA MORENO | I32: OFICINA DOWNTOWN CENTER MALL | K32: La Romana;La Romana;Katanga | L32: LA ROMANA-LA ROMANA-LA ROMANA-KATANGA-SANTA LUISA DE MARILLA-10-0-0-ESCUELA DE MANEJO JONAHTAN-C-8295125396-0-C-8097878547-0 | M32: La Romana | N32: LA ROMANA | O32: La Romana | P32: Katanga | Q32: SANTA LUISA DE MARIL | R32: 10 | S32: 0 | T32: 0 | U32: ESCUELA DE MANEJO JONAHTAN | V32: C | W32: 8295125396 | X32: 0 | Y32: C | Z32: 8097878547 | AA32: 0 | AE32: APPPOPULAR | AF32: 46203.738 | AG32: En proceso | AH32: TD- ENTREGADO | AI32: Gabriel | AJ32: PRINCIPAL | AL32: 46209 | AO32: Contactos Efectivos | AP32: !NENVIO A RESIDENCIA!NPROVINCIA // SANTO DOMINGO ESTE !N SECTOR// BARRIO KATANGA !NCALLE// STA LUISA DE MARILLAC !NNO.// 10!NREFE// PROXIMO A FUNDAION ANGELICA MATILDE BUGUE!NHORA// 8AM A 5PM !NTELE//8097878547!NCOMISCAT | AQ32: 8295125396
